[2023-05-01 09:59:10,170] INFO _log() L224   * Restarting with stat - call_trace=C:\Python311\Lib\site-packages\werkzeug\_internal.py L224 
[2023-05-01 09:59:11,874] INFO _log() L224   * Restarting with stat - call_trace=C:\Python311\Lib\site-packages\werkzeug\_internal.py L224 
[2023-05-01 09:59:14,381] INFO _log() L224   * Detected change in 'C:\\Projetos\\IPT\\desenvolvimento-full-stack\\desenvolvimento-full-stack-basico\\carros\\api\\app.py', reloading - call_trace=C:\Python311\Lib\site-packages\werkzeug\_internal.py L224 
[2023-05-01 09:59:14,514] INFO _log() L224   * Restarting with stat - call_trace=C:\Python311\Lib\site-packages\werkzeug\_internal.py L224 
[2023-05-01 09:59:22,223] WARNING add_carro() L63   Erro ao adicionar carro 'chevete', N√£o foi poss√≠vel salvar novo item :/ - call_trace=C:\Projetos\IPT\desenvolvimento-full-stack\desenvolvimento-full-stack-basico\carros\api\app.py L63  
[2023-05-01 09:59:22,225] INFO _log() L224  127.0.0.1 - - [01/May/2023 09:59:22] "[31m[1mPOST /carro HTTP/1.1[0m" 400 - - call_trace=C:\Python311\Lib\site-packages\werkzeug\_internal.py L224 
[2023-05-01 10:00:45,210] WARNING add_carro() L57   Erro ao adicionar carro 'chevete', Carro de mesmo nome j√° salvo na base :/ - call_trace=C:\Projetos\IPT\desenvolvimento-full-stack\desenvolvimento-full-stack-basico\carros\api\app.py L57  
[2023-05-01 10:00:45,213] INFO _log() L224  127.0.0.1 - - [01/May/2023 10:00:45] "[31m[1mPOST /carro HTTP/1.1[0m" 409 - - call_trace=C:\Python311\Lib\site-packages\werkzeug\_internal.py L224 
[2023-05-01 10:01:40,644] ERROR log_exception() L1449 Exception on /carros [GET] - call_trace=C:\Python311\Lib\site-packages\flask\app.py L1449
Traceback (most recent call last):
  File "C:\Python311\Lib\site-packages\flask\app.py", line 2073, in wsgi_app
    response = self.full_dispatch_request()
               ^^^^^^^^^^^^^^^^^^^^^^^^^^^^
  File "C:\Python311\Lib\site-packages\flask\app.py", line 1519, in full_dispatch_request
    rv = self.handle_user_exception(e)
         ^^^^^^^^^^^^^^^^^^^^^^^^^^^^^
  File "C:\Python311\Lib\site-packages\flask_cors\extension.py", line 165, in wrapped_function
    return cors_after_request(app.make_response(f(*args, **kwargs)))
                                                ^^^^^^^^^^^^^^^^^^
  File "C:\Python311\Lib\site-packages\flask\app.py", line 1517, in full_dispatch_request
    rv = self.dispatch_request()
         ^^^^^^^^^^^^^^^^^^^^^^^
  File "C:\Python311\Lib\site-packages\flask\app.py", line 1503, in dispatch_request
    return self.ensure_sync(self.view_functions[rule.endpoint])(**req.view_args)
           ^^^^^^^^^^^^^^^^^^^^^^^^^^^^^^^^^^^^^^^^^^^^^^^^^^^^^^^^^^^^^^^^^^^^^
  File "C:\Python311\Lib\site-packages\flask_openapi3\scaffold.py", line 109, in wrapper
    resp = _do_wrapper(
           ^^^^^^^^^^^^
  File "C:\Python311\Lib\site-packages\flask_openapi3\do_wrapper.py", line 135, in _do_wrapper
    response = func(**request_kwargs)
               ^^^^^^^^^^^^^^^^^^^^^^
  File "C:\Projetos\IPT\desenvolvimento-full-stack\desenvolvimento-full-stack-basico\carros\api\app.py", line 87, in get_carros
    return apresenta_Carros(carros), 200
           ^^^^^^^^^^^^^^^^^^^^^^^^
  File "C:\Projetos\IPT\desenvolvimento-full-stack\desenvolvimento-full-stack-basico\carros\api\schemas\carro.py", line 36, in apresenta_Carros
    "modelo": Carro.nome,
              ^^^^^^^^^^
AttributeError: 'Carro' object has no attribute 'nome'
[2023-05-01 10:01:40,660] INFO _log() L224  127.0.0.1 - - [01/May/2023 10:01:40] "[35m[1mGET /carros HTTP/1.1[0m" 500 - - call_trace=C:\Python311\Lib\site-packages\werkzeug\_internal.py L224 
[2023-05-01 10:02:26,265] INFO _log() L224   * Detected change in 'C:\\Projetos\\IPT\\desenvolvimento-full-stack\\desenvolvimento-full-stack-basico\\carros\\api\\schemas\\carro.py', reloading - call_trace=C:\Python311\Lib\site-packages\werkzeug\_internal.py L224 
[2023-05-01 10:02:26,383] INFO _log() L224   * Restarting with stat - call_trace=C:\Python311\Lib\site-packages\werkzeug\_internal.py L224 
[2023-05-01 10:02:29,000] INFO _log() L224   * Detected change in 'C:\\Projetos\\IPT\\desenvolvimento-full-stack\\desenvolvimento-full-stack-basico\\carros\\api\\schemas\\carro.py', reloading - call_trace=C:\Python311\Lib\site-packages\werkzeug\_internal.py L224 
[2023-05-01 10:02:29,131] INFO _log() L224   * Restarting with stat - call_trace=C:\Python311\Lib\site-packages\werkzeug\_internal.py L224 
[2023-05-01 10:02:31,709] INFO _log() L224   * Detected change in 'C:\\Projetos\\IPT\\desenvolvimento-full-stack\\desenvolvimento-full-stack-basico\\carros\\api\\schemas\\carro.py', reloading - call_trace=C:\Python311\Lib\site-packages\werkzeug\_internal.py L224 
[2023-05-01 10:02:31,921] INFO _log() L224   * Restarting with stat - call_trace=C:\Python311\Lib\site-packages\werkzeug\_internal.py L224 
[2023-05-01 10:02:35,786] INFO _log() L224  127.0.0.1 - - [01/May/2023 10:02:35] "GET /carros HTTP/1.1" 200 - - call_trace=C:\Python311\Lib\site-packages\werkzeug\_internal.py L224 
[2023-05-01 10:04:03,808] ERROR log_exception() L1449 Exception on /carro [GET] - call_trace=C:\Python311\Lib\site-packages\flask\app.py L1449
Traceback (most recent call last):
  File "C:\Python311\Lib\site-packages\flask\app.py", line 2073, in wsgi_app
    response = self.full_dispatch_request()
               ^^^^^^^^^^^^^^^^^^^^^^^^^^^^
  File "C:\Python311\Lib\site-packages\flask\app.py", line 1519, in full_dispatch_request
    rv = self.handle_user_exception(e)
         ^^^^^^^^^^^^^^^^^^^^^^^^^^^^^
  File "C:\Python311\Lib\site-packages\flask_cors\extension.py", line 165, in wrapped_function
    return cors_after_request(app.make_response(f(*args, **kwargs)))
                                                ^^^^^^^^^^^^^^^^^^
  File "C:\Python311\Lib\site-packages\flask\app.py", line 1517, in full_dispatch_request
    rv = self.dispatch_request()
         ^^^^^^^^^^^^^^^^^^^^^^^
  File "C:\Python311\Lib\site-packages\flask\app.py", line 1503, in dispatch_request
    return self.ensure_sync(self.view_functions[rule.endpoint])(**req.view_args)
           ^^^^^^^^^^^^^^^^^^^^^^^^^^^^^^^^^^^^^^^^^^^^^^^^^^^^^^^^^^^^^^^^^^^^^
  File "C:\Python311\Lib\site-packages\flask_openapi3\scaffold.py", line 109, in wrapper
    resp = _do_wrapper(
           ^^^^^^^^^^^^
  File "C:\Python311\Lib\site-packages\flask_openapi3\do_wrapper.py", line 135, in _do_wrapper
    response = func(**request_kwargs)
               ^^^^^^^^^^^^^^^^^^^^^^
  File "C:\Projetos\IPT\desenvolvimento-full-stack\desenvolvimento-full-stack-basico\carros\api\app.py", line 97, in get_carro
    carro_id = query.id
               ^^^^^^^^
AttributeError: 'CarroBuscaSchema' object has no attribute 'id'
[2023-05-01 10:04:03,819] INFO _log() L224  127.0.0.1 - - [01/May/2023 10:04:03] "[35m[1mGET /carro?modelo=chevete HTTP/1.1[0m" 500 - - call_trace=C:\Python311\Lib\site-packages\werkzeug\_internal.py L224 
[2023-05-01 10:04:14,379] ERROR log_exception() L1449 Exception on /carro [GET] - call_trace=C:\Python311\Lib\site-packages\flask\app.py L1449
Traceback (most recent call last):
  File "C:\Python311\Lib\site-packages\flask\app.py", line 2073, in wsgi_app
    response = self.full_dispatch_request()
               ^^^^^^^^^^^^^^^^^^^^^^^^^^^^
  File "C:\Python311\Lib\site-packages\flask\app.py", line 1519, in full_dispatch_request
    rv = self.handle_user_exception(e)
         ^^^^^^^^^^^^^^^^^^^^^^^^^^^^^
  File "C:\Python311\Lib\site-packages\flask_cors\extension.py", line 165, in wrapped_function
    return cors_after_request(app.make_response(f(*args, **kwargs)))
                                                ^^^^^^^^^^^^^^^^^^
  File "C:\Python311\Lib\site-packages\flask\app.py", line 1517, in full_dispatch_request
    rv = self.dispatch_request()
         ^^^^^^^^^^^^^^^^^^^^^^^
  File "C:\Python311\Lib\site-packages\flask\app.py", line 1503, in dispatch_request
    return self.ensure_sync(self.view_functions[rule.endpoint])(**req.view_args)
           ^^^^^^^^^^^^^^^^^^^^^^^^^^^^^^^^^^^^^^^^^^^^^^^^^^^^^^^^^^^^^^^^^^^^^
  File "C:\Python311\Lib\site-packages\flask_openapi3\scaffold.py", line 109, in wrapper
    resp = _do_wrapper(
           ^^^^^^^^^^^^
  File "C:\Python311\Lib\site-packages\flask_openapi3\do_wrapper.py", line 135, in _do_wrapper
    response = func(**request_kwargs)
               ^^^^^^^^^^^^^^^^^^^^^^
  File "C:\Projetos\IPT\desenvolvimento-full-stack\desenvolvimento-full-stack-basico\carros\api\app.py", line 97, in get_carro
    carro_id = query.id
               ^^^^^^^^
AttributeError: 'CarroBuscaSchema' object has no attribute 'id'
[2023-05-01 10:04:14,388] INFO _log() L224  127.0.0.1 - - [01/May/2023 10:04:14] "[35m[1mGET /carro?modelo=1 HTTP/1.1[0m" 500 - - call_trace=C:\Python311\Lib\site-packages\werkzeug\_internal.py L224 
[2023-05-01 10:05:06,746] INFO _log() L224   * Detected change in 'C:\\Projetos\\IPT\\desenvolvimento-full-stack\\desenvolvimento-full-stack-basico\\carros\\api\\app.py', reloading - call_trace=C:\Python311\Lib\site-packages\werkzeug\_internal.py L224 
[2023-05-01 10:05:06,873] INFO _log() L224   * Restarting with stat - call_trace=C:\Python311\Lib\site-packages\werkzeug\_internal.py L224 
[2023-05-01 10:05:10,507] INFO _log() L224   * Restarting with stat - call_trace=C:\Python311\Lib\site-packages\werkzeug\_internal.py L224 
[2023-05-01 10:05:19,255] INFO _log() L224   * Restarting with stat - call_trace=C:\Python311\Lib\site-packages\werkzeug\_internal.py L224 
[2023-05-01 10:05:38,159] WARNING get_carro() L107  Erro ao buscar carro 'chevete', Carro n√£o encontrado na base :/ - call_trace=C:\Projetos\IPT\desenvolvimento-full-stack\desenvolvimento-full-stack-basico\carros\api\app.py L107 
[2023-05-01 10:06:07,986] INFO _log() L224   * Restarting with stat - call_trace=C:\Python311\Lib\site-packages\werkzeug\_internal.py L224 
